<?xml version="1.0" encoding="UTF-8"?><testrun name="HsqldbUserDaoTest" project="usermanagement" tests="5" started="5" failures="0" errors="5" ignored="0">
  <testsuite name="ua.nure.cs.petrykin.usermanagement.db.HsqldbUserDaoTest" time="0.285">
    <testcase name="testFindAll" classname="ua.nure.cs.petrykin.usermanagement.db.HsqldbUserDaoTest" time="0.223">
      <error>ua.nure.cs.petrykin.usermanagement.db.DatabaseException: java.sql.SQLException: The database is already in use by another process: org.hsqldb.persist.NIOLockFile@25400ba[file =C:\Users\milan\workspace2\usermanagement\db\usermanagement.lck, exists=true, locked=false, valid=false, fl =null]: java.lang.Exception: checkHeartbeat(): lock file [C:\Users\milan\workspace2\usermanagement\db\usermanagement.lck] is presumably locked by another process.&#13;
	at ua.nure.cs.petrykin.usermanagement.db.ConnectionFactoryImpl.createConnection(ConnectionFactoryImpl.java:42)&#13;
	at ua.nure.cs.petrykin.usermanagement.db.HsqldbUserDaoTest.getConnection(HsqldbUserDaoTest.java:90)&#13;
	at org.dbunit.DatabaseTestCase.executeOperation(DatabaseTestCase.java:84)&#13;
	at org.dbunit.DatabaseTestCase.setUp(DatabaseTestCase.java:104)&#13;
	at ua.nure.cs.petrykin.usermanagement.db.HsqldbUserDaoTest.setUp(HsqldbUserDaoTest.java:29)&#13;
	at junit.framework.TestCase.runBare(TestCase.java:139)&#13;
	at junit.framework.TestResult$1.protect(TestResult.java:122)&#13;
	at junit.framework.TestResult.runProtected(TestResult.java:142)&#13;
	at junit.framework.TestResult.run(TestResult.java:125)&#13;
	at junit.framework.TestCase.run(TestCase.java:129)&#13;
	at junit.framework.TestSuite.runTest(TestSuite.java:252)&#13;
	at junit.framework.TestSuite.run(TestSuite.java:247)&#13;
	at org.eclipse.jdt.internal.junit.runner.junit3.JUnit3TestReference.run(JUnit3TestReference.java:121)&#13;
	at org.eclipse.jdt.internal.junit.runner.TestExecution.run(TestExecution.java:38)&#13;
	at org.eclipse.jdt.internal.junit.runner.RemoteTestRunner.runTests(RemoteTestRunner.java:459)&#13;
	at org.eclipse.jdt.internal.junit.runner.RemoteTestRunner.runTests(RemoteTestRunner.java:678)&#13;
	at org.eclipse.jdt.internal.junit.runner.RemoteTestRunner.run(RemoteTestRunner.java:382)&#13;
	at org.eclipse.jdt.internal.junit.runner.RemoteTestRunner.main(RemoteTestRunner.java:192)&#13;
Caused by: java.sql.SQLException: The database is already in use by another process: org.hsqldb.persist.NIOLockFile@25400ba[file =C:\Users\milan\workspace2\usermanagement\db\usermanagement.lck, exists=true, locked=false, valid=false, fl =null]: java.lang.Exception: checkHeartbeat(): lock file [C:\Users\milan\workspace2\usermanagement\db\usermanagement.lck] is presumably locked by another process.&#13;
	at org.hsqldb.jdbc.Util.sqlException(Unknown Source)&#13;
	at org.hsqldb.jdbc.jdbcConnection.&lt;init&gt;(Unknown Source)&#13;
	at org.hsqldb.jdbcDriver.getConnection(Unknown Source)&#13;
	at org.hsqldb.jdbcDriver.connect(Unknown Source)&#13;
	at java.sql.DriverManager.getConnection(Unknown Source)&#13;
	at java.sql.DriverManager.getConnection(Unknown Source)&#13;
	at ua.nure.cs.petrykin.usermanagement.db.ConnectionFactoryImpl.createConnection(ConnectionFactoryImpl.java:40)&#13;
	... 17 more&#13;
&#13;
</error>
    </testcase>
    <testcase name="testFind" classname="ua.nure.cs.petrykin.usermanagement.db.HsqldbUserDaoTest" time="0.017">
      <error>ua.nure.cs.petrykin.usermanagement.db.DatabaseException: java.sql.SQLException: The database is already in use by another process: org.hsqldb.persist.NIOLockFile@25400ba[file =C:\Users\milan\workspace2\usermanagement\db\usermanagement.lck, exists=true, locked=false, valid=false, fl =null]: java.lang.Exception: checkHeartbeat(): lock file [C:\Users\milan\workspace2\usermanagement\db\usermanagement.lck] is presumably locked by another process.&#13;
	at ua.nure.cs.petrykin.usermanagement.db.ConnectionFactoryImpl.createConnection(ConnectionFactoryImpl.java:42)&#13;
	at ua.nure.cs.petrykin.usermanagement.db.HsqldbUserDaoTest.getConnection(HsqldbUserDaoTest.java:90)&#13;
	at org.dbunit.DatabaseTestCase.executeOperation(DatabaseTestCase.java:84)&#13;
	at org.dbunit.DatabaseTestCase.setUp(DatabaseTestCase.java:104)&#13;
	at ua.nure.cs.petrykin.usermanagement.db.HsqldbUserDaoTest.setUp(HsqldbUserDaoTest.java:29)&#13;
	at junit.framework.TestCase.runBare(TestCase.java:139)&#13;
	at junit.framework.TestResult$1.protect(TestResult.java:122)&#13;
	at junit.framework.TestResult.runProtected(TestResult.java:142)&#13;
	at junit.framework.TestResult.run(TestResult.java:125)&#13;
	at junit.framework.TestCase.run(TestCase.java:129)&#13;
	at junit.framework.TestSuite.runTest(TestSuite.java:252)&#13;
	at junit.framework.TestSuite.run(TestSuite.java:247)&#13;
	at org.eclipse.jdt.internal.junit.runner.junit3.JUnit3TestReference.run(JUnit3TestReference.java:121)&#13;
	at org.eclipse.jdt.internal.junit.runner.TestExecution.run(TestExecution.java:38)&#13;
	at org.eclipse.jdt.internal.junit.runner.RemoteTestRunner.runTests(RemoteTestRunner.java:459)&#13;
	at org.eclipse.jdt.internal.junit.runner.RemoteTestRunner.runTests(RemoteTestRunner.java:678)&#13;
	at org.eclipse.jdt.internal.junit.runner.RemoteTestRunner.run(RemoteTestRunner.java:382)&#13;
	at org.eclipse.jdt.internal.junit.runner.RemoteTestRunner.main(RemoteTestRunner.java:192)&#13;
Caused by: java.sql.SQLException: The database is already in use by another process: org.hsqldb.persist.NIOLockFile@25400ba[file =C:\Users\milan\workspace2\usermanagement\db\usermanagement.lck, exists=true, locked=false, valid=false, fl =null]: java.lang.Exception: checkHeartbeat(): lock file [C:\Users\milan\workspace2\usermanagement\db\usermanagement.lck] is presumably locked by another process.&#13;
	at org.hsqldb.jdbc.Util.sqlException(Unknown Source)&#13;
	at org.hsqldb.jdbc.jdbcConnection.&lt;init&gt;(Unknown Source)&#13;
	at org.hsqldb.jdbcDriver.getConnection(Unknown Source)&#13;
	at org.hsqldb.jdbcDriver.connect(Unknown Source)&#13;
	at java.sql.DriverManager.getConnection(Unknown Source)&#13;
	at java.sql.DriverManager.getConnection(Unknown Source)&#13;
	at ua.nure.cs.petrykin.usermanagement.db.ConnectionFactoryImpl.createConnection(ConnectionFactoryImpl.java:40)&#13;
	... 17 more&#13;
&#13;
</error>
    </testcase>
    <testcase name="testCreate" classname="ua.nure.cs.petrykin.usermanagement.db.HsqldbUserDaoTest" time="0.019">
      <error>ua.nure.cs.petrykin.usermanagement.db.DatabaseException: java.sql.SQLException: The database is already in use by another process: org.hsqldb.persist.NIOLockFile@25400ba[file =C:\Users\milan\workspace2\usermanagement\db\usermanagement.lck, exists=true, locked=false, valid=false, fl =null]: java.lang.Exception: checkHeartbeat(): lock file [C:\Users\milan\workspace2\usermanagement\db\usermanagement.lck] is presumably locked by another process.&#13;
	at ua.nure.cs.petrykin.usermanagement.db.ConnectionFactoryImpl.createConnection(ConnectionFactoryImpl.java:42)&#13;
	at ua.nure.cs.petrykin.usermanagement.db.HsqldbUserDaoTest.getConnection(HsqldbUserDaoTest.java:90)&#13;
	at org.dbunit.DatabaseTestCase.executeOperation(DatabaseTestCase.java:84)&#13;
	at org.dbunit.DatabaseTestCase.setUp(DatabaseTestCase.java:104)&#13;
	at ua.nure.cs.petrykin.usermanagement.db.HsqldbUserDaoTest.setUp(HsqldbUserDaoTest.java:29)&#13;
	at junit.framework.TestCase.runBare(TestCase.java:139)&#13;
	at junit.framework.TestResult$1.protect(TestResult.java:122)&#13;
	at junit.framework.TestResult.runProtected(TestResult.java:142)&#13;
	at junit.framework.TestResult.run(TestResult.java:125)&#13;
	at junit.framework.TestCase.run(TestCase.java:129)&#13;
	at junit.framework.TestSuite.runTest(TestSuite.java:252)&#13;
	at junit.framework.TestSuite.run(TestSuite.java:247)&#13;
	at org.eclipse.jdt.internal.junit.runner.junit3.JUnit3TestReference.run(JUnit3TestReference.java:121)&#13;
	at org.eclipse.jdt.internal.junit.runner.TestExecution.run(TestExecution.java:38)&#13;
	at org.eclipse.jdt.internal.junit.runner.RemoteTestRunner.runTests(RemoteTestRunner.java:459)&#13;
	at org.eclipse.jdt.internal.junit.runner.RemoteTestRunner.runTests(RemoteTestRunner.java:678)&#13;
	at org.eclipse.jdt.internal.junit.runner.RemoteTestRunner.run(RemoteTestRunner.java:382)&#13;
	at org.eclipse.jdt.internal.junit.runner.RemoteTestRunner.main(RemoteTestRunner.java:192)&#13;
Caused by: java.sql.SQLException: The database is already in use by another process: org.hsqldb.persist.NIOLockFile@25400ba[file =C:\Users\milan\workspace2\usermanagement\db\usermanagement.lck, exists=true, locked=false, valid=false, fl =null]: java.lang.Exception: checkHeartbeat(): lock file [C:\Users\milan\workspace2\usermanagement\db\usermanagement.lck] is presumably locked by another process.&#13;
	at org.hsqldb.jdbc.Util.sqlException(Unknown Source)&#13;
	at org.hsqldb.jdbc.jdbcConnection.&lt;init&gt;(Unknown Source)&#13;
	at org.hsqldb.jdbcDriver.getConnection(Unknown Source)&#13;
	at org.hsqldb.jdbcDriver.connect(Unknown Source)&#13;
	at java.sql.DriverManager.getConnection(Unknown Source)&#13;
	at java.sql.DriverManager.getConnection(Unknown Source)&#13;
	at ua.nure.cs.petrykin.usermanagement.db.ConnectionFactoryImpl.createConnection(ConnectionFactoryImpl.java:40)&#13;
	... 17 more&#13;
&#13;
</error>
    </testcase>
    <testcase name="testDelete" classname="ua.nure.cs.petrykin.usermanagement.db.HsqldbUserDaoTest" time="0.014">
      <error>ua.nure.cs.petrykin.usermanagement.db.DatabaseException: java.sql.SQLException: The database is already in use by another process: org.hsqldb.persist.NIOLockFile@25400ba[file =C:\Users\milan\workspace2\usermanagement\db\usermanagement.lck, exists=true, locked=false, valid=false, fl =null]: java.lang.Exception: checkHeartbeat(): lock file [C:\Users\milan\workspace2\usermanagement\db\usermanagement.lck] is presumably locked by another process.&#13;
	at ua.nure.cs.petrykin.usermanagement.db.ConnectionFactoryImpl.createConnection(ConnectionFactoryImpl.java:42)&#13;
	at ua.nure.cs.petrykin.usermanagement.db.HsqldbUserDaoTest.getConnection(HsqldbUserDaoTest.java:90)&#13;
	at org.dbunit.DatabaseTestCase.executeOperation(DatabaseTestCase.java:84)&#13;
	at org.dbunit.DatabaseTestCase.setUp(DatabaseTestCase.java:104)&#13;
	at ua.nure.cs.petrykin.usermanagement.db.HsqldbUserDaoTest.setUp(HsqldbUserDaoTest.java:29)&#13;
	at junit.framework.TestCase.runBare(TestCase.java:139)&#13;
	at junit.framework.TestResult$1.protect(TestResult.java:122)&#13;
	at junit.framework.TestResult.runProtected(TestResult.java:142)&#13;
	at junit.framework.TestResult.run(TestResult.java:125)&#13;
	at junit.framework.TestCase.run(TestCase.java:129)&#13;
	at junit.framework.TestSuite.runTest(TestSuite.java:252)&#13;
	at junit.framework.TestSuite.run(TestSuite.java:247)&#13;
	at org.eclipse.jdt.internal.junit.runner.junit3.JUnit3TestReference.run(JUnit3TestReference.java:121)&#13;
	at org.eclipse.jdt.internal.junit.runner.TestExecution.run(TestExecution.java:38)&#13;
	at org.eclipse.jdt.internal.junit.runner.RemoteTestRunner.runTests(RemoteTestRunner.java:459)&#13;
	at org.eclipse.jdt.internal.junit.runner.RemoteTestRunner.runTests(RemoteTestRunner.java:678)&#13;
	at org.eclipse.jdt.internal.junit.runner.RemoteTestRunner.run(RemoteTestRunner.java:382)&#13;
	at org.eclipse.jdt.internal.junit.runner.RemoteTestRunner.main(RemoteTestRunner.java:192)&#13;
Caused by: java.sql.SQLException: The database is already in use by another process: org.hsqldb.persist.NIOLockFile@25400ba[file =C:\Users\milan\workspace2\usermanagement\db\usermanagement.lck, exists=true, locked=false, valid=false, fl =null]: java.lang.Exception: checkHeartbeat(): lock file [C:\Users\milan\workspace2\usermanagement\db\usermanagement.lck] is presumably locked by another process.&#13;
	at org.hsqldb.jdbc.Util.sqlException(Unknown Source)&#13;
	at org.hsqldb.jdbc.jdbcConnection.&lt;init&gt;(Unknown Source)&#13;
	at org.hsqldb.jdbcDriver.getConnection(Unknown Source)&#13;
	at org.hsqldb.jdbcDriver.connect(Unknown Source)&#13;
	at java.sql.DriverManager.getConnection(Unknown Source)&#13;
	at java.sql.DriverManager.getConnection(Unknown Source)&#13;
	at ua.nure.cs.petrykin.usermanagement.db.ConnectionFactoryImpl.createConnection(ConnectionFactoryImpl.java:40)&#13;
	... 17 more&#13;
&#13;
</error>
    </testcase>
    <testcase name="testUpdate" classname="ua.nure.cs.petrykin.usermanagement.db.HsqldbUserDaoTest" time="0.01">
      <error>ua.nure.cs.petrykin.usermanagement.db.DatabaseException: java.sql.SQLException: The database is already in use by another process: org.hsqldb.persist.NIOLockFile@25400ba[file =C:\Users\milan\workspace2\usermanagement\db\usermanagement.lck, exists=true, locked=false, valid=false, fl =null]: java.lang.Exception: checkHeartbeat(): lock file [C:\Users\milan\workspace2\usermanagement\db\usermanagement.lck] is presumably locked by another process.&#13;
	at ua.nure.cs.petrykin.usermanagement.db.ConnectionFactoryImpl.createConnection(ConnectionFactoryImpl.java:42)&#13;
	at ua.nure.cs.petrykin.usermanagement.db.HsqldbUserDaoTest.getConnection(HsqldbUserDaoTest.java:90)&#13;
	at org.dbunit.DatabaseTestCase.executeOperation(DatabaseTestCase.java:84)&#13;
	at org.dbunit.DatabaseTestCase.setUp(DatabaseTestCase.java:104)&#13;
	at ua.nure.cs.petrykin.usermanagement.db.HsqldbUserDaoTest.setUp(HsqldbUserDaoTest.java:29)&#13;
	at junit.framework.TestCase.runBare(TestCase.java:139)&#13;
	at junit.framework.TestResult$1.protect(TestResult.java:122)&#13;
	at junit.framework.TestResult.runProtected(TestResult.java:142)&#13;
	at junit.framework.TestResult.run(TestResult.java:125)&#13;
	at junit.framework.TestCase.run(TestCase.java:129)&#13;
	at junit.framework.TestSuite.runTest(TestSuite.java:252)&#13;
	at junit.framework.TestSuite.run(TestSuite.java:247)&#13;
	at org.eclipse.jdt.internal.junit.runner.junit3.JUnit3TestReference.run(JUnit3TestReference.java:121)&#13;
	at org.eclipse.jdt.internal.junit.runner.TestExecution.run(TestExecution.java:38)&#13;
	at org.eclipse.jdt.internal.junit.runner.RemoteTestRunner.runTests(RemoteTestRunner.java:459)&#13;
	at org.eclipse.jdt.internal.junit.runner.RemoteTestRunner.runTests(RemoteTestRunner.java:678)&#13;
	at org.eclipse.jdt.internal.junit.runner.RemoteTestRunner.run(RemoteTestRunner.java:382)&#13;
	at org.eclipse.jdt.internal.junit.runner.RemoteTestRunner.main(RemoteTestRunner.java:192)&#13;
Caused by: java.sql.SQLException: The database is already in use by another process: org.hsqldb.persist.NIOLockFile@25400ba[file =C:\Users\milan\workspace2\usermanagement\db\usermanagement.lck, exists=true, locked=false, valid=false, fl =null]: java.lang.Exception: checkHeartbeat(): lock file [C:\Users\milan\workspace2\usermanagement\db\usermanagement.lck] is presumably locked by another process.&#13;
	at org.hsqldb.jdbc.Util.sqlException(Unknown Source)&#13;
	at org.hsqldb.jdbc.jdbcConnection.&lt;init&gt;(Unknown Source)&#13;
	at org.hsqldb.jdbcDriver.getConnection(Unknown Source)&#13;
	at org.hsqldb.jdbcDriver.connect(Unknown Source)&#13;
	at java.sql.DriverManager.getConnection(Unknown Source)&#13;
	at java.sql.DriverManager.getConnection(Unknown Source)&#13;
	at ua.nure.cs.petrykin.usermanagement.db.ConnectionFactoryImpl.createConnection(ConnectionFactoryImpl.java:40)&#13;
	... 17 more&#13;
&#13;
</error>
    </testcase>
  </testsuite>
</testrun>
